Failure # 1 (occurred at 2023-12-08_00-42-22)
[36mray::DQN.train()[39m (pid=15132, ip=127.0.0.1, actor_id=048952c5de72e2bb52f5eff201000000, repr=DQN)
  File "python\ray\_raylet.pyx", line 1675, in ray._raylet.execute_task
  File "python\ray\_raylet.pyx", line 1615, in ray._raylet.execute_task.function_executor
  File "C:\Users\Checkout\anaconda3\envs\rl3\lib\site-packages\ray\_private\function_manager.py", line 726, in actor_method_executor
    return method(__ray_actor, *args, **kwargs)
  File "C:\Users\Checkout\anaconda3\envs\rl3\lib\site-packages\ray\util\tracing\tracing_helper.py", line 467, in _resume_span
    return method(self, *_args, **_kwargs)
  File "C:\Users\Checkout\anaconda3\envs\rl3\lib\site-packages\ray\tune\trainable\trainable.py", line 342, in train
    raise skipped from exception_cause(skipped)
  File "C:\Users\Checkout\anaconda3\envs\rl3\lib\site-packages\ray\tune\trainable\trainable.py", line 339, in train
    result = self.step()
  File "C:\Users\Checkout\anaconda3\envs\rl3\lib\site-packages\ray\util\tracing\tracing_helper.py", line 467, in _resume_span
    return method(self, *_args, **_kwargs)
  File "C:\Users\Checkout\anaconda3\envs\rl3\lib\site-packages\ray\rllib\algorithms\algorithm.py", line 853, in step
    results, train_iter_ctx = self._run_one_training_iteration()
  File "C:\Users\Checkout\anaconda3\envs\rl3\lib\site-packages\ray\util\tracing\tracing_helper.py", line 467, in _resume_span
    return method(self, *_args, **_kwargs)
  File "C:\Users\Checkout\anaconda3\envs\rl3\lib\site-packages\ray\rllib\algorithms\algorithm.py", line 2854, in _run_one_training_iteration
    results = self.training_step()
  File "C:\Users\Checkout\anaconda3\envs\rl3\lib\site-packages\ray\util\tracing\tracing_helper.py", line 467, in _resume_span
    return method(self, *_args, **_kwargs)
  File "C:\Users\Checkout\anaconda3\envs\rl3\lib\site-packages\ray\rllib\algorithms\dqn\dqn.py", line 429, in training_step
    train_batch = sample_min_n_steps_from_buffer(
  File "C:\Users\Checkout\anaconda3\envs\rl3\lib\site-packages\ray\rllib\utils\replay_buffers\utils.py", line 147, in sample_min_n_steps_from_buffer
    batch = replay_buffer.sample(num_items=1)
TypeError: PrioritizedReplayBuffer.sample() missing 1 required positional argument: 'beta'
